basic.schematics.tree = {
  size = {x=7, y=8, z=7},
  yslice_prob = {
    {ypos=0, prob=254},
    {ypos=1, prob=254},
    {ypos=2, prob=126},
    {ypos=3, prob=254},
    {ypos=4, prob=254},
    {ypos=5, prob=254},
    {ypos=6, prob=254},
    {ypos=7, prob=254},
  },
  data = {

    -- z=0, y=0
    {name="air", prob=0, param2=0},
    {name="air", prob=0, param2=0},
    {name="air", prob=0, param2=0},
    {name="air", prob=0, param2=0},
    {name="air", prob=0, param2=0},
    {name="air", prob=0, param2=0},
    {name="air", prob=0, param2=0},

    -- z=0, y=1
    {name="air", prob=0, param2=0},
    {name="air", prob=0, param2=0},
    {name="air", prob=0, param2=0},
    {name="air", prob=0, param2=0},
    {name="air", prob=0, param2=0},
    {name="air", prob=0, param2=0},
    {name="air", prob=0, param2=0},

    -- z=0, y=2
    {name="air", prob=0, param2=0},
    {name="air", prob=0, param2=0},
    {name="air", prob=0, param2=0},
    {name="air", prob=0, param2=0},
    {name="air", prob=0, param2=0},
    {name="air", prob=0, param2=0},
    {name="air", prob=0, param2=0},

    -- z=0, y=3
    {name="air", prob=0, param2=0},
    {name="air", prob=0, param2=0},
    {name="air", prob=0, param2=0},
    {name="air", prob=0, param2=0},
    {name="air", prob=0, param2=0},
    {name="air", prob=0, param2=0},
    {name="air", prob=0, param2=0},

    -- z=0, y=4
    {name="air", prob=0, param2=0},
    {name="air", prob=0, param2=0},
    {name="basic:leaves", prob=222, param2=0},
    {name="basic:leaves", prob=254, param2=0},
    {name="basic:leaves", prob=222, param2=0},
    {name="air", prob=0, param2=0},
    {name="air", prob=0, param2=0},

    -- z=0, y=5
    {name="air", prob=0, param2=0},
    {name="air", prob=0, param2=0},
    {name="air", prob=0, param2=0},
    {name="basic:leaves", prob=222, param2=0},
    {name="air", prob=0, param2=0},
    {name="air", prob=0, param2=0},
    {name="air", prob=0, param2=0},

    -- z=0, y=6
    {name="air", prob=0, param2=0},
    {name="air", prob=0, param2=0},
    {name="air", prob=0, param2=0},
    {name="air", prob=0, param2=0},
    {name="air", prob=0, param2=0},
    {name="air", prob=0, param2=0},
    {name="air", prob=0, param2=0},

    -- z=0, y=7
    {name="air", prob=0, param2=0},
    {name="air", prob=0, param2=0},
    {name="air", prob=0, param2=0},
    {name="air", prob=0, param2=0},
    {name="air", prob=0, param2=0},
    {name="air", prob=0, param2=0},
    {name="air", prob=0, param2=0},

    -- z=1, y=0
    {name="air", prob=0, param2=0},
    {name="air", prob=0, param2=0},
    {name="air", prob=0, param2=0},
    {name="air", prob=0, param2=0},
    {name="air", prob=0, param2=0},
    {name="air", prob=0, param2=0},
    {name="air", prob=0, param2=0},

    -- z=1, y=1
    {name="air", prob=0, param2=0},
    {name="air", prob=0, param2=0},
    {name="air", prob=0, param2=0},
    {name="air", prob=0, param2=0},
    {name="air", prob=0, param2=0},
    {name="air", prob=0, param2=0},
    {name="air", prob=0, param2=0},

    -- z=1, y=2
    {name="air", prob=0, param2=0},
    {name="air", prob=0, param2=0},
    {name="air", prob=0, param2=0},
    {name="air", prob=0, param2=0},
    {name="air", prob=0, param2=0},
    {name="air", prob=0, param2=0},
    {name="air", prob=0, param2=0},

    -- z=1, y=3
    {name="air", prob=0, param2=0},
    {name="air", prob=0, param2=0},
    {name="air", prob=0, param2=0},
    {name="air", prob=0, param2=0},
    {name="air", prob=0, param2=0},
    {name="air", prob=0, param2=0},
    {name="air", prob=0, param2=0},

    -- z=1, y=4
    {name="air", prob=0, param2=0},
    {name="basic:leaves", prob=254, param2=0},
    {name="basic:leaves", prob=254, param2=0},
    {name="basic:apple", prob=62, param2=0},
    {name="basic:leaves", prob=254, param2=0},
    {name="basic:leaves", prob=254, param2=0},
    {name="air", prob=0, param2=0},

    -- z=1, y=5
    {name="air", prob=0, param2=0},
    {name="basic:leaves", prob=222, param2=0},
    {name="basic:leaves", prob=254, param2=0},
    {name="basic:leaves", prob=254, param2=0},
    {name="basic:leaves", prob=254, param2=0},
    {name="basic:leaves", prob=222, param2=0},
    {name="air", prob=0, param2=0},

    -- z=1, y=6
    {name="air", prob=0, param2=0},
    {name="air", prob=0, param2=0},
    {name="basic:leaves", prob=222, param2=0},
    {name="basic:leaves", prob=254, param2=0},
    {name="basic:leaves", prob=222, param2=0},
    {name="air", prob=0, param2=0},
    {name="air", prob=0, param2=0},

    -- z=1, y=7
    {name="air", prob=0, param2=0},
    {name="air", prob=0, param2=0},
    {name="air", prob=0, param2=0},
    {name="air", prob=0, param2=0},
    {name="air", prob=0, param2=0},
    {name="air", prob=0, param2=0},
    {name="air", prob=0, param2=0},

    -- z=2, y=0
    {name="air", prob=0, param2=0},
    {name="air", prob=0, param2=0},
    {name="air", prob=0, param2=0},
    {name="air", prob=0, param2=0},
    {name="air", prob=0, param2=0},
    {name="air", prob=0, param2=0},
    {name="air", prob=0, param2=0},

    -- z=2, y=1
    {name="air", prob=0, param2=0},
    {name="air", prob=0, param2=0},
    {name="air", prob=0, param2=0},
    {name="air", prob=0, param2=0},
    {name="air", prob=0, param2=0},
    {name="air", prob=0, param2=0},
    {name="air", prob=0, param2=0},

    -- z=2, y=2
    {name="air", prob=0, param2=0},
    {name="air", prob=0, param2=0},
    {name="air", prob=0, param2=0},
    {name="air", prob=0, param2=0},
    {name="air", prob=0, param2=0},
    {name="air", prob=0, param2=0},
    {name="air", prob=0, param2=0},

    -- z=2, y=3
    {name="air", prob=0, param2=0},
    {name="air", prob=0, param2=0},
    {name="air", prob=0, param2=0},
    {name="air", prob=0, param2=0},
    {name="air", prob=0, param2=0},
    {name="air", prob=0, param2=0},
    {name="air", prob=0, param2=0},

    -- z=2, y=4
    {name="basic:leaves", prob=222, param2=0},
    {name="basic:leaves", prob=254, param2=0},
    {name="basic:wood", prob=254, param2=0, force_place=true},
    {name="air", prob=0, param2=0},
    {name="air", prob=0, param2=0},
    {name="basic:leaves", prob=254, param2=0},
    {name="basic:leaves", prob=222, param2=0},

    -- z=2, y=5
    {name="air", prob=0, param2=0},
    {name="basic:leaves", prob=254, param2=0},
    {name="basic:leaves", prob=254, param2=0},
    {name="air", prob=0, param2=0},
    {name="basic:wood", prob=254, param2=0, force_place=true},
    {name="basic:leaves", prob=254, param2=0},
    {name="air", prob=0, param2=0},

    -- z=2, y=6
    {name="air", prob=0, param2=0},
    {name="basic:leaves", prob=222, param2=0},
    {name="basic:leaves", prob=254, param2=0},
    {name="basic:leaves", prob=254, param2=0},
    {name="basic:leaves", prob=254, param2=0},
    {name="basic:leaves", prob=222, param2=0},
    {name="air", prob=0, param2=0},

    -- z=2, y=7
    {name="air", prob=0, param2=0},
    {name="air", prob=0, param2=0},
    {name="air", prob=0, param2=0},
    {name="basic:leaves", prob=222, param2=0},
    {name="air", prob=0, param2=0},
    {name="air", prob=0, param2=0},
    {name="air", prob=0, param2=0},

    -- z=3, y=0
    {name="air", prob=0, param2=0},
    {name="air", prob=0, param2=0},
    {name="air", prob=0, param2=0},
    {name="basic:wood", prob=254, param2=0, force_place=true},
    {name="air", prob=0, param2=0},
    {name="air", prob=0, param2=0},
    {name="air", prob=0, param2=0},

    -- z=3, y=1
    {name="air", prob=0, param2=0},
    {name="air", prob=0, param2=0},
    {name="air", prob=0, param2=0},
    {name="basic:wood", prob=254, param2=0, force_place=true},
    {name="air", prob=0, param2=0},
    {name="air", prob=0, param2=0},
    {name="air", prob=0, param2=0},

    -- z=3, y=2
    {name="air", prob=0, param2=0},
    {name="air", prob=0, param2=0},
    {name="air", prob=0, param2=0},
    {name="basic:wood", prob=254, param2=0, force_place=true},
    {name="air", prob=0, param2=0},
    {name="air", prob=0, param2=0},
    {name="air", prob=0, param2=0},

    -- z=3, y=3
    {name="air", prob=0, param2=0},
    {name="air", prob=0, param2=0},
    {name="air", prob=0, param2=0},
    {name="basic:wood", prob=254, param2=0, force_place=true},
    {name="air", prob=0, param2=0},
    {name="air", prob=0, param2=0},
    {name="air", prob=0, param2=0},

    -- z=3, y=4
    {name="basic:leaves", prob=254, param2=0},
    {name="basic:apple", prob=62, param2=0},
    {name="air", prob=0, param2=0},
    {name="basic:wood", prob=254, param2=0, force_place=true},
    {name="air", prob=0, param2=0},
    {name="basic:apple", prob=62, param2=0},
    {name="basic:leaves", prob=254, param2=0},

    -- z=3, y=5
    {name="basic:leaves", prob=222, param2=0},
    {name="basic:leaves", prob=254, param2=0},
    {name="air", prob=0, param2=0},
    {name="air", prob=0, param2=0},
    {name="air", prob=0, param2=0},
    {name="basic:leaves", prob=254, param2=0},
    {name="basic:leaves", prob=222, param2=0},

    -- z=3, y=6
    {name="air", prob=0, param2=0},
    {name="basic:leaves", prob=254, param2=0},
    {name="basic:leaves", prob=254, param2=0},
    {name="basic:leaves", prob=254, param2=0},
    {name="basic:leaves", prob=254, param2=0},
    {name="basic:leaves", prob=254, param2=0},
    {name="air", prob=0, param2=0},

    -- z=3, y=7
    {name="air", prob=0, param2=0},
    {name="air", prob=0, param2=0},
    {name="basic:leaves", prob=222, param2=0},
    {name="basic:leaves", prob=254, param2=0},
    {name="basic:leaves", prob=222, param2=0},
    {name="air", prob=0, param2=0},
    {name="air", prob=0, param2=0},

    -- z=4, y=0
    {name="air", prob=0, param2=0},
    {name="air", prob=0, param2=0},
    {name="air", prob=0, param2=0},
    {name="air", prob=0, param2=0},
    {name="air", prob=0, param2=0},
    {name="air", prob=0, param2=0},
    {name="air", prob=0, param2=0},

    -- z=4, y=1
    {name="air", prob=0, param2=0},
    {name="air", prob=0, param2=0},
    {name="air", prob=0, param2=0},
    {name="air", prob=0, param2=0},
    {name="air", prob=0, param2=0},
    {name="air", prob=0, param2=0},
    {name="air", prob=0, param2=0},

    -- z=4, y=2
    {name="air", prob=0, param2=0},
    {name="air", prob=0, param2=0},
    {name="air", prob=0, param2=0},
    {name="air", prob=0, param2=0},
    {name="air", prob=0, param2=0},
    {name="air", prob=0, param2=0},
    {name="air", prob=0, param2=0},

    -- z=4, y=3
    {name="air", prob=0, param2=0},
    {name="air", prob=0, param2=0},
    {name="air", prob=0, param2=0},
    {name="air", prob=0, param2=0},
    {name="air", prob=0, param2=0},
    {name="air", prob=0, param2=0},
    {name="air", prob=0, param2=0},

    -- z=4, y=4
    {name="basic:leaves", prob=222, param2=0},
    {name="basic:leaves", prob=254, param2=0},
    {name="air", prob=0, param2=0},
    {name="air", prob=0, param2=0},
    {name="basic:wood", prob=254, param2=0, force_place=true},
    {name="basic:leaves", prob=254, param2=0},
    {name="basic:leaves", prob=222, param2=0},

    -- z=4, y=5
    {name="air", prob=0, param2=0},
    {name="basic:leaves", prob=254, param2=0},
    {name="basic:wood", prob=254, param2=0, force_place=true},
    {name="air", prob=0, param2=0},
    {name="basic:leaves", prob=254, param2=0},
    {name="basic:leaves", prob=254, param2=0},
    {name="air", prob=0, param2=0},

    -- z=4, y=6
    {name="air", prob=0, param2=0},
    {name="basic:leaves", prob=222, param2=0},
    {name="basic:leaves", prob=254, param2=0},
    {name="basic:leaves", prob=254, param2=0},
    {name="basic:leaves", prob=254, param2=0},
    {name="basic:leaves", prob=222, param2=0},
    {name="air", prob=0, param2=0},

    -- z=4, y=7
    {name="air", prob=0, param2=0},
    {name="air", prob=0, param2=0},
    {name="air", prob=0, param2=0},
    {name="basic:leaves", prob=222, param2=0},
    {name="air", prob=0, param2=0},
    {name="air", prob=0, param2=0},
    {name="air", prob=0, param2=0},

    -- z=5, y=0
    {name="air", prob=0, param2=0},
    {name="air", prob=0, param2=0},
    {name="air", prob=0, param2=0},
    {name="air", prob=0, param2=0},
    {name="air", prob=0, param2=0},
    {name="air", prob=0, param2=0},
    {name="air", prob=0, param2=0},

    -- z=5, y=1
    {name="air", prob=0, param2=0},
    {name="air", prob=0, param2=0},
    {name="air", prob=0, param2=0},
    {name="air", prob=0, param2=0},
    {name="air", prob=0, param2=0},
    {name="air", prob=0, param2=0},
    {name="air", prob=0, param2=0},

    -- z=5, y=2
    {name="air", prob=0, param2=0},
    {name="air", prob=0, param2=0},
    {name="air", prob=0, param2=0},
    {name="air", prob=0, param2=0},
    {name="air", prob=0, param2=0},
    {name="air", prob=0, param2=0},
    {name="air", prob=0, param2=0},

    -- z=5, y=3
    {name="air", prob=0, param2=0},
    {name="air", prob=0, param2=0},
    {name="air", prob=0, param2=0},
    {name="air", prob=0, param2=0},
    {name="air", prob=0, param2=0},
    {name="air", prob=0, param2=0},
    {name="air", prob=0, param2=0},

    -- z=5, y=4
    {name="air", prob=0, param2=0},
    {name="basic:leaves", prob=254, param2=0},
    {name="basic:leaves", prob=254, param2=0},
    {name="basic:apple", prob=62, param2=0},
    {name="basic:leaves", prob=254, param2=0},
    {name="basic:leaves", prob=254, param2=0},
    {name="air", prob=0, param2=0},

    -- z=5, y=5
    {name="air", prob=0, param2=0},
    {name="basic:leaves", prob=222, param2=0},
    {name="basic:leaves", prob=254, param2=0},
    {name="basic:leaves", prob=254, param2=0},
    {name="basic:leaves", prob=254, param2=0},
    {name="basic:leaves", prob=222, param2=0},
    {name="air", prob=0, param2=0},

    -- z=5, y=6
    {name="air", prob=0, param2=0},
    {name="air", prob=0, param2=0},
    {name="basic:leaves", prob=222, param2=0},
    {name="basic:leaves", prob=254, param2=0},
    {name="basic:leaves", prob=222, param2=0},
    {name="air", prob=0, param2=0},
    {name="air", prob=0, param2=0},

    -- z=5, y=7
    {name="air", prob=0, param2=0},
    {name="air", prob=0, param2=0},
    {name="air", prob=0, param2=0},
    {name="air", prob=0, param2=0},
    {name="air", prob=0, param2=0},
    {name="air", prob=0, param2=0},
    {name="air", prob=0, param2=0},

    -- z=6, y=0
    {name="air", prob=0, param2=0},
    {name="air", prob=0, param2=0},
    {name="air", prob=0, param2=0},
    {name="air", prob=0, param2=0},
    {name="air", prob=0, param2=0},
    {name="air", prob=0, param2=0},
    {name="air", prob=0, param2=0},

    -- z=6, y=1
    {name="air", prob=0, param2=0},
    {name="air", prob=0, param2=0},
    {name="air", prob=0, param2=0},
    {name="air", prob=0, param2=0},
    {name="air", prob=0, param2=0},
    {name="air", prob=0, param2=0},
    {name="air", prob=0, param2=0},

    -- z=6, y=2
    {name="air", prob=0, param2=0},
    {name="air", prob=0, param2=0},
    {name="air", prob=0, param2=0},
    {name="air", prob=0, param2=0},
    {name="air", prob=0, param2=0},
    {name="air", prob=0, param2=0},
    {name="air", prob=0, param2=0},

    -- z=6, y=3
    {name="air", prob=0, param2=0},
    {name="air", prob=0, param2=0},
    {name="air", prob=0, param2=0},
    {name="air", prob=0, param2=0},
    {name="air", prob=0, param2=0},
    {name="air", prob=0, param2=0},
    {name="air", prob=0, param2=0},

    -- z=6, y=4
    {name="air", prob=0, param2=0},
    {name="air", prob=0, param2=0},
    {name="basic:leaves", prob=222, param2=0},
    {name="basic:leaves", prob=254, param2=0},
    {name="basic:leaves", prob=222, param2=0},
    {name="air", prob=0, param2=0},
    {name="air", prob=0, param2=0},

    -- z=6, y=5
    {name="air", prob=0, param2=0},
    {name="air", prob=0, param2=0},
    {name="air", prob=0, param2=0},
    {name="basic:leaves", prob=222, param2=0},
    {name="air", prob=0, param2=0},
    {name="air", prob=0, param2=0},
    {name="air", prob=0, param2=0},

    -- z=6, y=6
    {name="air", prob=0, param2=0},
    {name="air", prob=0, param2=0},
    {name="air", prob=0, param2=0},
    {name="air", prob=0, param2=0},
    {name="air", prob=0, param2=0},
    {name="air", prob=0, param2=0},
    {name="air", prob=0, param2=0},

    -- z=6, y=7
    {name="air", prob=0, param2=0},
    {name="air", prob=0, param2=0},
    {name="air", prob=0, param2=0},
    {name="air", prob=0, param2=0},
    {name="air", prob=0, param2=0},
    {name="air", prob=0, param2=0},
    {name="air", prob=0, param2=0},
  },
}
